Workbook

Sheet Itinerary
A1: Date | B1: Main Itinerary | C1: Optional Activities | E1: Outfits
A2: 45897 | B2: Fly to Naples 4:46 Take off (SYR - ORD, 2H35M, ORD - NAP, AA 4134, AA 180) | C2: Packing List
A3: =A2+1 -> 45898 | B3: Arrive Naples 1:00 PM 2:00 PM - Welcome Pickups to hotel (reservation) Check into Relais sul Mare Boutique Hotel 3:00 PM (reservation) TODO: Find nearby attractions and pizza spots Dinner (7:30) 50 Kalò - Piazza della Repubblica (reservation) | C3: welcomepickups | D3: Dinner Options: Palazzo Petrucci Ristorante Il Miracolo dei Pesci Ristorante Reginella La Scialuppa 50 kalo
A4: =A3+1 -> 45899 | B4: Naples/Capri 8:10 board ferry to Capri (reservation, boards 8:40, leaves 9:10) - Depart from Molo Beverello Check out of Relais sul Mare 11:30 AM Check into La Residenza Capri 3:00 PM (reservation)? Buy wine and snacks for boat day tomorrow (bring in discreet tote) Dinner (8 PM) at Villa Margherita (reservation) | C4: Cafe: Cafe Caso Hike: Gardens of Augustus Hike: Via Krupp Shop: Via Camerelle Boat Provisions: Enoteca La Vineria, Other Recommendations Pool: Hotel
A5: =A4+1 -> 45900 | B5: Capri Boat Day 9:00 AM - 4:00 PM - Marina Piccola (ticket, reservation) TODO: Find landmarks Dinner (8 PM) at Da Paolino (reservation) | E5: Linen pants, Rag & Bone polo, leather loafers
A6: =A5+1 -> 45901 | B6: Capri La Fontelina (reservation, opens 9:30 AM, lunch 1PM, must check in before 1 PM) Dinner (7:00 PM) at Pullali (reservation) | C6: Night Club: Anema e Core
A7: =A6+1 -> 45902 | B7: Capri to Ravello Check out of La Residenza Capri 11:00 AM 10:45 board Ferry leaving at 11:45 to Amalfi (reservation) Ride from Giancarlo +393394432880 to Ravello (75 euro) (email) Check into Hotel Rufolo 2:00 PM (Reservation, King Size Bed Confirmation) TODO: Find Dinner | C7: Pool: Hotel
A8: =A7+1 -> 45903 | B8: Ravello Dinner (7:30 PM) at Rossellinis (reservation) | C8: Garden: Giardini Principessa di Piemonte Shopping: Local Artisan Shops Wine Bar: Enotavola Wine Bar
A9: =A8+1 -> 45904 | B9: Ravello to Positano Check out of Hotel Rufolo 11:00 AM Mamma Agata (bring 720 Euro, 9:45 AM - 4 PM, reservation, vegetarian option confirmation) TOOD: Book driver to Praiano (4:30 recommended by Mamma Agata) Check into Hotel Savoia 2:00 PM (Reservation) Dinner: See casual options on Right | C9: Dinner: Casual nearby options | D9: Dinner Options: Ristorante La Cambusa Casa e Bottega Ristorante Il Capitano Valle dei Mulini Ristorante Da Bruno Il Tridente Positano | F9: Zass Ristorante Bruno Chez Black
A10: =A9+1 -> 45905 | B10: Positano Arienzo beach club Beach time 11:10 AM, Lunch Time 2:30 PM (times adjustable, Reservation: PVTPTL) Dinner: 8:00 PM at Buca di Bacco (reservation) | C10: Booking Link
A11: =A10+1 -> 45906 | B11: Positano Boat day 2: 9:00 AM - 1:00 PM Grassi Junior Boats (reservation, ticket) Cruise toward the Fjord of Furore, Conca dei Marini, or around Li Galli Islands TODO: Add boat day spots to map TODO: Da Adolfo lunch reservation Dinner: Rada at 9:00 PM (reservation) requested outdoor seating with a view (email) | C11: Night Club: Music on the Rocks Rooftop Cocktail: Frano's Bar (if open) Booking Link
A12: =A11+1 -> 45907 | B12: Positano Lunch: Il Pirata at 1:00 PM (reservation) TODO: Plan day - options Vespa day? Hiking day? Dinner: Adamo ed Eva at 7:00 PM (reservation) requested outdoor seating with a view (email) | C12: Options for Day Hike: Path of the gods Vespa: Destination options Farm: Limoncello Tour
A13: =A12+1 -> 45908 | B13: Check out of Hotel Savoia 11:00 AM TODO: Book car from hotel to Airport 12:00 PM Take off (NAP - PHL 3H - SYR, AA 781, AA 5950)
B17: :)

Sheet Chelsea
A1: https://sierrainthecity.com/best-restaurants-in-positano/
A2: chat gpt
A3: manus

Sheet Amalfi
A1: 45817 | B1: Map | E1: Todo Immediate | F1: Major Items to Book | G1: Status | I1: Ideas | J1: Status | M1: Capri Hotels | R1: Paiano/Positano Hotels | V1: TODO | W1: Spots
A2: 45817 | B2: Travel Assistant | E2: Capri boat dat | F2: La Fontelina (Capri) | G2: Booked for Mon 9/1 | I2: L'Olivo and Mote Solare Chair Lift (Capri) | M2: Sina Flora | N2: 3071 | O2: Booked, free cancellation before Aug 23 | Q2: Praiano | R2: Casa Angelina | S2: Near One Fire Beach Club | V2: Find spots for Capri | W2: Cafes
A3: 45818 | B3: Naples HoodMap | E3: Da Luigis | F3: La Tagliata (Positano) | G3: Requested 6/17 | L3: A little far | M3: Villa Marini | N3: 2883 | Q3: Positano | R3: Casa Nilde | S3: BnB | T3: Booked, cancel before Aug 21 | V3: Find spots for Ravello | W3: Aperitivo
A4: 45817 | B4: ChatGPT: Amafli Deep-Dive | E4: Restaurants in capri | F4: Ristorante Il Pirata (Praiano) | L4: 1. Delux suite wtih spa bath is sick | M4: Palazzo M Capri | N4: 4398 | O4: No pool? | Q4: Positano | R4: Your home in the heart of Positano - centralissima | V4: Find spots for Positano | W4: Rooftop bar
A5: 45813 | B5: Apple Notes: Activity Ideas | F5: da Paolino | G5: Booked for Sun Aug 31 | L5: Anacapri | M5: Boutique Hotel Casa Mariantonia | N5: 1833 | Q5: Positano | R5: Villa Joseph Talamo | W5: Gardens/Vistas
A6: 45817 | B6: ChatGPT (Live): Casual discussion about beach clubs | F6: Capri Boat day | G6: Booked for Sun Aug 31 | L6: Dated | M6: Grand Hotel Quisisana | N6: 3584 | O6: No sea view | Q6: Positano | R6: Hotel Poseidon | W6: Hikes
A7: 45817 | B7: Packing List | F7: Mamma Agata | G7: Booked for Thu 9/4 | L7: Exceptional | M7: Pazziella Garden & Suites | N7: 3875 | O7: Chase | Q7: Positano | R7: Hotel Savoia | W7: Wine bar
A8: 45818 | B8: Manus: Itinerary | F8: Rossellini's, Palazzo Avino | G8: Booked for Wed 9/3 | L8: 2. Cool ground | M8: Villa Certosa | N8: 3702 | O8: Chase is better | Q8: Positano | R8: La Caravella di Positano | W8: Wine tasting
F9: Boat day in Praiano? | M9: Hotel Villa Ceselle (Value Option) | Q9: Positano | R9: Hotel Montemare | S9: Via Pasitea 119, 84017 Positano, Italy | W9: Lunch spots
F10: Naples Hotel | G10: Booked Relais sul Mare | J10: Todo tm: | L10: Wonderful | M10: Capri Tiberio Palace | N10: 4065 | Q10: Positano | R10: Villa Joseph Talamo | S10: 41 Via Guglielmo Marconi, 84017 Positano, Italy | W10: Beaches
B11: Positano Todo | D11: Important nearby: | F11: Da Luigis in Capri | I11: Done | J11: Figure out dates there | L11: Seaside, far, free cancellation | M11: Jumeirah Capri Palace | N11: 4685 | Q11: Positano | R11: Villa Dani | S11: Via del Saracino, 84017 Positano, Italy | W11: Shopping areas
B12: Drink Spot reservations | D12: Cafes | F12: Travel Insurance | I12: Done | J12: Start requesting restaurants on left | L12: Apartment | M12: Sunbliss Capri | N12: 1194 | W12: Historical sites
B13: Hotel | D13: Sandwich/Pastry Shops | F13: Arienzo in Positano | G13: Booked for 9/5 | I13: Done | J13: Ask how to best book boat day, where, cost, and type (blue grotto, personal boat, private tours?) | M13: Punta Tragara | N13: 10237
B14: Rooftop cocktails at Hotel Le Sirenuse | D14: Gelaterias | F14: Spiaggia di Playa in Positano | I14: Done | J14: Book hotel for Capri | M14: Villa Marina Capri
B15: Sunset dinners in Positano | D15: Rooftop/Waterfront/Scenic drinks | F15: Add Buca di Bacco to Dining List | G15: Added to consolidated map, reservations available | I15: Done | J15: Add flight times to itinerary | M15: Hotel La Vega | O15: Booking.com only
D16: Wine bars | F16: Finalize Capri dining | I16: Done | J16: Book hotel for Naples | K16: Grand Hotel Parkers | M16: La Residenza Capri
D17: Walks/Hikes | F17: Find nearby lunch spots, walks, attractions | J17: Book dinner for Naples night 1
A18: Cost Tracker | D18: Night Clubs/Night Life
A19: Relais sul Mare | F19: To Factor In | M19: Chiaia Hotels
A20: Hotel Savoia | D20: Map Layers: | F20: Fiordo di Furore | M20: Grand Hotel Santa Lucia
A21: La Fontelina | D21: Main Events | F21: Marina di Praia | M21: Caruso Place Boutique & Wellness Suites
A22: Arienzo | D22: Curated Options | M22: Relais sul Mare Boutique Hotel | N22: Cheap sea view
A23: Capri Blue Boats | D23: All | F23: Other small todo
A24: Grassi Junior Boats | F24: Find cafes nearby to hotels for coffee/breakfast | M24: Paiano/Positano Hotels
A25: Mamma Agata | F25: Find lunch spots nearby to hotels | L25: Praiano | M25: Casa Angelina | N25: Near One Fire Beach Club
A26: Da Paolino | F26: Find a few casual dinner spots | L26: Positano | M26: Casa Nilde | N26: BnB
A27: Rosselinis | F27: Find "optional" nearby attractions (e.g. villas to explore)
F28: Book transportation between hotels
F29: Le Monzù, Capri
F30: L'Olivo, Capri
A31: Prompts | F31: Vespa day in Praiano?
A32: Itinerary | B32: Hi! My girlfriend (29F) and I (33M) are planning a romantic trip to the Amalfi Coast from August 30 to September 8 (9 nights, 10 days). It’s our first time in Italy, and we’re prioritizing relaxation, scenic beauty, romance, and well-curated experiences over high-effort city touring. We’re New Yorkers, so we want to avoid anything that feels like a Times Square/cruise ship/tourist trap vibe — no cheap souvenir stands, no English-only menus, no tourist junk zones. That said, we’re totally fine with places that are popular or Instagrammable as long as they’re visually stunning, tasteful, and offer a genuine or luxurious experience (like a cliffside restaurant or a boutique hotel with views). We’d like to: Fly into Naples (arriving Aug 30), spend 1 night for the culture and pizza Ferry to Capri for 1-3 nights to explore beaches, views, and maybe a boat day. Ferry to the Amalfi Coast, staying the reset of our nights in scenic towns like Ravello, Praiano, or Conca dei Marini — open to mixing between them. Fly out of Naples on Sept 8. We’re open to renting a car if it makes things easier, but it seems ferries with a mix of private transfers and vespas might be the simplest route. We’d love help finalizing: Which towns to base ourselves in (and for how long). A day-by-day structure using “anchor activities” and optional extras. Boutique hotel or lodging suggestions in each area. Restaurant, beach club, or boat day ideas that match our taste. Best use of ferries, private drivers, or transfer timing. Here were some high-level things we were interested in generally before settling on Amalfi as our destination: - [ ] Beach day (e.g. one lined with umbrellas) - [ ] Beach club - [ ] Vespa riding - [ ] Wine tasting tour (foot, bike, or vespa, or one single location without movement if easier) - [ ] Grotta Palazzese dinner (this is in Puglia, but we'd love something with a similar memorable stunning view) - [ ] Boat day - [ ] Aperol spritz rooftop sunset - [ ] Good authentic local food - [ ] Cooking class (normal/authentic or crazy and fun like La Tagliata cooking class in Positano) - [ ] Hike (e.g. along costal cliffside or in historic towns) - [ ] If there are any notable spas, thermal pools, or ancient bath houses in the region we might be up for checking them out but that's not a priority for diverting travel When planning think: romantic, adventurous, beautiful, and upscale — but never tacky. Thanks! | F32: L'Olivo and Mote Solare Chair Lift (Capri)
A33: Maps | B33: Thanks, can you compile all the places you recommended into a table with the following columns: Name: The name of the location Region: The town, city, neighborhood, or region Type: The type of location (e.g. hotel, Restaurant (lunch), Restaurant (dinner) Cafe, Gelateria, Rooftop Bar, Speakeasy, etc) Emoji: A representative emoji to be used on the map as an icon. Description: A description of the spot and its general vibe Special Notes: Any special considerations (must order items, dress code, cool historical facts, etc) Hours: Hours of operation (if applicable) Cost Range: Indication of how much 2 people would be expected to spend in a visit (in USD) Address: The full address (including country) if available LatLong: The latitude and Longitude separated by a comma and space
A34: Map Options | B34: Can you also recommend a mix of spots nearby that are in our general area and might be good to know about in case we are feeling spontaneous (so not as itinerary-oriented and more options list). Feel free to use my list or sprinkle in things we don't know about. Think places like renowned cafes, pizzerias, gelato shops, shopping places, wine windows, rooftop bars, wine bars, etc. Anything casual that might be fun to visit quickly while attending to a larger agenda. Can you come up with at least three (but preferably more) recommendations for each?
A35: Chiaia | B35: My girlfriend (29F) and I (33M) are staying a night or two in the Chiaia region of Naples before leaving to Capri for a few days. We are from NYC and like good food, good drinks, romantic scenery, exploring, and adventure. Can you recommend some hotels in the ~$200 to ~$400 USD range that are nice to stay in for dates 8/28 to 8/30? Can you also compile a list of good restaurants (pref a few on the water and a few inland that stand on their own merit), cool bars, cool cafes, cool rooftops for drinks, gelato spots, pizza spots, nightlife, and anything else that is a cool cultural experience for the area (or immediately adjacent) that we can explore while waiting to go to Capri? Think recommendations that would be suitable for theinfatuation.com, eater.com, or a well-regarded and chic travel blog or Instagram account.
A36: Maps 2

Sheet Consolidated Map
A1: Name | B1: Region | C1: Type | D1: Emoji | E1: Description | F1: Special Notes | G1: Hours | H1: Cost Range | I1: Address | J1: LatLong | K1: Latitude | L1: Longitude | M1: Google Maps | N1: Recommended By | O1: Plan | P1: Trip Segment | Q1: Hotel | R1: Walking Distance | S1: Driving Distance | T1: Curated
A2: Buonocore Gelateria & Bakery | B2: Capri town | C2: Bakery / Gelateria / Cafe | D2: 🍦 | E2: Famous bakery and gelateria with fresh panini, focaccia, and pastries. Very popular with locals and tourists alike. | F2: Smell the waffle cones to find it. Great for takeaway. Try the lemon granita or focaccia. | G2: 10:00–23:00 | H2: $10–$25 | I2: Via Vittorio Emanuele, 35, 80073 Capri NA, Italy | J2: 40.5504793, 14.2435663 | K2: 40.550479 | L2: 14.243566 | M2: https://www.google.com/maps/search/Buonocore%20Gelateria%20%26%20Bakery%2C%20Capri%2C%20Italy | N2: ChatGPT | O2: ChatGPT Capri Boat Day Wine Shops and Bakeries | P2: =VLOOKUP(B2,$V$3:$W$100,2,0) -> Capri | Q2: =VLOOKUP(P2,$X$3:$Y$6,2,0)&", "&P2&", Italy" -> La Residenza, Capri, Italy | R2: =VLOOKUP(A2,'Travel Times'!$A$1:$E$1000,4,0) -> 3 mins | S2: =VLOOKUP(A2,'Travel Times'!$A$1:$E$1000,5,0) -> 1 min
A3: Ristorante Lo Sfizio | B3: Capri (Via Tiberio) | C3: Casual Eatery / Bakery | D3: 🥪 | E3: Local favorite for rustic sandwiches, pizza by the slice, and simple, hearty baked goods. | F3: Perfect for takeaway or a quick bite. Affordable and local vibe. | G3: 12:00–15:00, 19:00–23:00 (closed Tuesdays) | H3: $20–$40 | I3: Via Tiberio, 7/e, 80073 Capri NA, Italy | J3: 40.552373, 14.250934 | K3: 40.552373 | L3: 14.250934 | M3: https://www.google.com/maps/search/Ristorante%20Lo%20Sfizio%2C%20Capri%2C%20Italy | N3: ChatGPT | O3: ChatGPT Capri Boat Day Wine Shops and Bakeries | P3: =VLOOKUP(B3,$V$3:$W$100,2,0) -> Capri | Q3: =VLOOKUP(P3,$X$3:$Y$6,2,0)&", "&P3&", Italy" -> La Residenza, Capri, Italy | R3: =VLOOKUP(A3,'Travel Times'!$A$1:$E$1000,4,0) -> 14 mins | S3: =VLOOKUP(A3,'Travel Times'!$A$1:$E$1000,5,0) -> 6 mins | V3: Capri town | W3: Capri | X3: Capri | Y3: La Residenza
A4: Caffè Caso | B4: Capri town | C4: Cafe | D4: ☕ | E4: Charming sidewalk café with espresso, croissants, and light snacks. | F4: Good for a quick stop before heading to the marina. Get the cornetto al limone. | G4: 07:30–21:00 | H4: $10–$20 | I4: Piazza Umberto I, 4, 80073 Capri NA, Italy | J4: 40.5508286, 14.2427963 | K4: 40.550829 | L4: 14.242796 | M4: https://www.google.com/maps/search/Caff%C3%A8%20Caso%2C%20Capri%2C%20Italy | N4: ChatGPT | O4: ChatGPT Capri Boat Day Wine Shops and Bakeries | P4: =VLOOKUP(B4,$V$3:$W$100,2,0) -> Capri | Q4: =VLOOKUP(P4,$X$3:$Y$6,2,0)&", "&P4&", Italy" -> La Residenza, Capri, Italy | R4: =VLOOKUP(A4,'Travel Times'!$A$1:$E$1000,4,0) -> 4 mins | S4: =VLOOKUP(A4,'Travel Times'!$A$1:$E$1000,5,0) -> 1 min | V4: Capri (Via Tiberio) | W4: Capri | X4: Naples | Y4: Relais sul Mare Boutique Hotel
A5: Panificio Fornaretto | B5: Capri town | C5: Bakery | D5: 🍞 | E5: Rustic neighborhood bakery specializing in fresh bread, pizza bianca, and taralli. | F5: No frills but great for boat snacks and local baked goods. | G5: 07:00–14:00, 17:00–20:00 | H5: $10–$20 | I5: Via Trieste e Trento, 20, 80071 Anacapri NA, Italy | J5: 40.55462790000001, 14.2168974 | K5: 40.554628 | L5: 14.216897 | M5: https://www.google.com/maps/search/Panificio%20Fornaretto%2C%20Capri%2C%20Italy | N5: ChatGPT | O5: ChatGPT Capri Boat Day Wine Shops and Bakeries | P5: =VLOOKUP(B5,$V$3:$W$100,2,0) -> Capri | Q5: =VLOOKUP(P5,$X$3:$Y$6,2,0)&", "&P5&", Italy" -> La Residenza, Capri, Italy | R5: =VLOOKUP(A5,'Travel Times'!$A$1:$E$1000,4,0) -> 52 mins | S5: =VLOOKUP(A5,'Travel Times'!$A$1:$E$1000,5,0) -> 11 mins | V5: Marina Grande | W5: Capri | X5: Ravello | Y5: Hotel Rufolo
A6: Enoteca Truglio | B6: Capri town | C6: Wine Shop | D6: 🍷 | E6: Local wine shop offering a curated selection of Campania wines, prosecco, and local snacks. | F6: Staff can recommend wine for boat days. Ask for Falanghina or Biancolella. | G6: 09:00–13:00, 16:30–20:00 | H6: $20–$60 | I6: 80076 Capri, Metropolitan City of Naples, Italy | J6: 40.5542182, 14.2400251 | K6: 40.554218 | L6: 14.240025 | M6: https://www.google.com/maps/search/Enoteca%20Truglio%2C%20Capri%2C%20Italy | N6: ChatGPT | O6: ChatGPT Capri Boat Day Wine Shops and Bakeries | P6: =VLOOKUP(B6,$V$3:$W$100,2,0) -> Capri | Q6: =VLOOKUP(P6,$X$3:$Y$6,2,0)&", "&P6&", Italy" -> La Residenza, Capri, Italy | R6: =VLOOKUP(A6,'Travel Times'!$A$1:$E$1000,4,0) -> 16 mins | S6: =VLOOKUP(A6,'Travel Times'!$A$1:$E$1000,5,0) -> 7 mins | V6: Matermania/Arco Naturale | W6: Capri | X6: Positano | Y6: Hotel Savoia
A7: Enoteca La Vineria | B7: Capri town | C7: Wine Shop | D7: 🥂 | E7: Upscale wine shop near the Piazzetta with excellent white wines, prosecco, and picnic-ready options. | F7: Offers chilled bottles. Great for romantic boat provisioning. | G7: 10:00–13:00, 16:00–20:00 | H7: $30–$80 | I7: Via Gino Alfani, 39, 80058 Torre Annunziata NA, Italy | J7: 40.5507259, 14.2429 | K7: 40.550726 | L7: 14.2429 | M7: https://www.google.com/maps/search/Enoteca%20La%20Vineria%2C%20Capri%2C%20Italy | N7: ChatGPT | O7: ChatGPT Capri Boat Day Wine Shops and Bakeries | P7: =VLOOKUP(B7,$V$3:$W$100,2,0) -> Capri | Q7: =VLOOKUP(P7,$X$3:$Y$6,2,0)&", "&P7&", Italy" -> La Residenza, Capri, Italy | R7: =VLOOKUP(A7,'Travel Times'!$A$1:$E$1000,4,0) -> 4 mins | S7: =VLOOKUP(A7,'Travel Times'!$A$1:$E$1000,5,0) -> 1 min | V7: Capri | W7: Capri
A8: Da Giorgio | B8: Capri Town | C8: Restaurant (Lunch/Dinner) | D8: 🍽️ | E8: Reddit favorite with amazing view of Capri harbor, Mount Vesuvius, and the coast. Decades of delicious dishes, excellent seafood delicacies | F8: Recommended by local hotel owners, 7-minute taxi from Marina Grande, stunning Bay of Naples views | G8: 12:00 PM - 3:00 PM & 7:00 PM - 11:00 PM | H8: $80-120 USD for 2 | I8: Via Roma, 34, 80076 Capri NA, Italy | J8: 40.55018400000001, 14.241639 | K8: 40.550184 | L8: 14.241639 | M8: https://www.google.com/maps/search/Da%20Giorgio%2C%20Capri%2C%20Italy | N8: Manus | O8: Manus Capri Restaurants | P8: =VLOOKUP(B8,$V$3:$W$100,2,0) -> Capri | Q8: =VLOOKUP(P8,$X$3:$Y$6,2,0)&", "&P8&", Italy" -> La Residenza, Capri, Italy | R8: =VLOOKUP(A8,'Travel Times'!$A$1:$E$1000,4,0) -> 6 mins | S8: =VLOOKUP(A8,'Travel Times'!$A$1:$E$1000,5,0) -> 1 min | V8: Naples | W8: Naples
A9: Aurora | B9: Capri Town | C9: Restaurant (Dinner) | D9: 🍽️ | E9: Historic gastronomic museum with fun loud singalong atmosphere. Truffle pizzas, delicate pastas, classic seafood dishes. Oldest restaurant in Capri | F9: Must try the cataloni dish, lively metro vibe, walls adorned with photographs, more than a restaurant | G9: 7:00 PM - 11:30 PM | H9: $90-140 USD for 2 | I9: Via Fuorlovado, 18, 80073 Capri NA, Italy | J9: 40.550878, 14.2450572 | K9: 40.550878 | L9: 14.245057 | M9: https://www.google.com/maps/search/Aurora%2C%20Capri%2C%20Italy | N9: Manus | O9: Manus Capri Restaurants | P9: =VLOOKUP(B9,$V$3:$W$100,2,0) -> Capri | Q9: =VLOOKUP(P9,$X$3:$Y$6,2,0)&", "&P9&", Italy" -> La Residenza, Capri, Italy | R9: =VLOOKUP(A9,'Travel Times'!$A$1:$E$1000,4,0) -> 5 mins | S9: =VLOOKUP(A9,'Travel Times'!$A$1:$E$1000,5,0) -> 1 min | V9: Ravello | W9: Ravello
A10: Da Gemma | B10: Marina Grande | C10: Restaurant (Lunch/Dinner) | D10: 🍽️ | E10: #1 rated restaurant on TripAdvisor with 4.7/5 rating from 1,513 reviews. Seafood and Mediterranean cuisine, homemade pasta | F10: Consistently highest-rated, family-owned, reliable excellence, proven track record | G10: 12:00 PM - 3:00 PM & 7:00 PM - 11:00 PM | H10: $70-110 USD for 2 | I10: Via Cristoforo Colombo, 7, 80073 Capri NA, Italy | J10: 40.5562249, 14.2388268 | K10: 40.556225 | L10: 14.238827 | M10: https://www.google.com/maps/search/Da%20Gemma%2C%20Capri%2C%20Italy | N10: Manus | O10: Manus Capri Restaurants | P10: =VLOOKUP(B10,$V$3:$W$100,2,0) -> Capri | Q10: =VLOOKUP(P10,$X$3:$Y$6,2,0)&", "&P10&", Italy" -> La Residenza, Capri, Italy | R10: =VLOOKUP(A10,'Travel Times'!$A$1:$E$1000,4,0) -> 23 mins | S10: =VLOOKUP(A10,'Travel Times'!$A$1:$E$1000,5,0) -> 9 mins | V10: Wine Experience, Ravello | W10: Ravello
A11: Le Grottelle | B11: Matermania/Arco Naturale | C11: Restaurant (Dinner) | D11: 🍽️ | E11: Hidden gem nestled inside natural caves near Arco Naturale. Dining experience like no other, 20-minute walk from main tourist hub | F11: Special occasion dinner, unique cave dining experience, off the beaten path, advance reservations essential | G11: 7:00 PM - 11:00 PM | H11: $100-150 USD for 2 | I11: Via Arco Naturale, 13, 80073 Capri NA, Italy | J11: 40.5494786, 14.2541823 | K11: 40.549479 | L11: 14.254182 | M11: https://www.google.com/maps/search/Le%20Grottelle%2C%20Capri%2C%20Italy | N11: Manus | O11: Manus Capri Restaurants | P11: =VLOOKUP(B11,$V$3:$W$100,2,0) -> Capri | Q11: =VLOOKUP(P11,$X$3:$Y$6,2,0)&", "&P11&", Italy" -> La Residenza, Capri, Italy | R11: =VLOOKUP(A11,'Travel Times'!$A$1:$E$1000,4,0) -> 20 mins | S11: =VLOOKUP(A11,'Travel Times'!$A$1:$E$1000,5,0) -> #ERROR! | V11: Praiano | W11: Positano
A12: Villa Verde | B12: Capri Town | C12: Restaurant (Dinner) | D12: 🍽️ | E12: White table-clothed restaurant in old town great for big groups. Combines dinner with nightlife, beautiful outdoor patio dining | F12: Great for groups, evening entertainment with dinner, away from crowds, lively evening scene | G12: 7:00 PM - 12:00 AM | H12: $90-130 USD for 2 | I12: Via Sella Orta, 6, 80073 Capri NA, Italy | J12: 40.55006849999999, 14.2445107 | K12: 40.550069 | L12: 14.244511 | M12: https://www.google.com/maps/search/Villa%20Verde%2C%20Capri%2C%20Italy | N12: Manus | O12: Manus Capri Restaurants | P12: =VLOOKUP(B12,$V$3:$W$100,2,0) -> Capri | Q12: =VLOOKUP(P12,$X$3:$Y$6,2,0)&", "&P12&", Italy" -> La Residenza, Capri, Italy | R12: =VLOOKUP(A12,'Travel Times'!$A$1:$E$1000,4,0) -> 2 mins | S12: =VLOOKUP(A12,'Travel Times'!$A$1:$E$1000,5,0) -> 1 min | T12: Lunch: selected by Chelsea | V12: Conca dei Marini | W12: Positano
A13: Lo Smeraldo | B13: Marina Grande | C13: Restaurant (Lunch/Dinner) | D13: 🍽️ | E13: Family-owned seaside restaurant with patio overlooking the water. Amazing coastline views, fresh seafood specialties | F13: Unbeatable seaside dining, patio over the water, romantic seafood dinner with water views | G13: 12:00 PM - 3:00 PM & 7:00 PM - 10:30 PM | H13: $80-120 USD for 2 | I13: Piazza Vittoria, 1, 80073 Capri NA, Italy | J13: 40.5504764, 14.243448 | K13: 40.550476 | L13: 14.243448 | M13: https://www.google.com/maps/search/Lo%20Smeraldo%2C%20Capri%2C%20Italy | N13: Manus | O13: Manus Capri Restaurants | P13: =VLOOKUP(B13,$V$3:$W$100,2,0) -> Capri | Q13: =VLOOKUP(P13,$X$3:$Y$6,2,0)&", "&P13&", Italy" -> La Residenza, Capri, Italy | R13: =VLOOKUP(A13,'Travel Times'!$A$1:$E$1000,4,0) -> 22 mins | S13: =VLOOKUP(A13,'Travel Times'!$A$1:$E$1000,5,0) -> 10 mins | V13: Monastero Santa Rosa | W13: Positano
A14: Pescheria Le Botteghe | B14: Capri Town | C14: Restaurant (Lunch) | D14: 🍽️ | E14: Fish market that also serves incredibly fresh seafood. Buy fresh fish and have it prepared on-site, market-to-table concept | F14: Freshest possible seafood, authentic local experience, not touristy, ultimate freshness for seafood lovers | G14: 10:00 AM - 3:00 PM | H14: $60-90 USD for 2 | I14: Via le Botteghe, 19, 80076 Capri NA, Italy | J14: 40.550782, 14.2433042 | K14: 40.550782 | L14: 14.243304 | M14: https://www.google.com/maps/search/Pescheria%20Le%20Botteghe%2C%20Capri%2C%20Italy | N14: Manus | O14: Manus Capri Restaurants | P14: =VLOOKUP(B14,$V$3:$W$100,2,0) -> Capri | Q14: =VLOOKUP(P14,$X$3:$Y$6,2,0)&", "&P14&", Italy" -> La Residenza, Capri, Italy | R14: =VLOOKUP(A14,'Travel Times'!$A$1:$E$1000,4,0) -> 4 mins | S14: =VLOOKUP(A14,'Travel Times'!$A$1:$E$1000,5,0) -> 1 min | V14: Positano | W14: Positano
A15: Lo Sfizio | B15: Capri Town | C15: Restaurant (Lunch/Dinner) | D15: 🥪 | E15: Local favorite mentioned in food tours, authentic neighborhood spot. Traditional Italian dishes with good value | F15: Casual authentic meal, frequented by locals, less touristy atmosphere, good value dining | G15: 12:00 PM - 3:00 PM & 7:00 PM - 10:30 PM | H15: $50-80 USD for 2 | I15: Via Tiberio, 7/e, 80073 Capri NA, Italy | J15: 40.552373, 14.250934 | K15: 40.552373 | L15: 14.250934 | M15: https://www.google.com/maps/search/Lo%20Sfizio%2C%20Capri%2C%20Italy | N15: Manus | O15: Manus Capri Restaurants | P15: =VLOOKUP(B15,$V$3:$W$100,2,0) -> Capri | Q15: =VLOOKUP(P15,$X$3:$Y$6,2,0)&", "&P15&", Italy" -> La Residenza, Capri, Italy | R15: =VLOOKUP(A15,'Travel Times'!$A$1:$E$1000,4,0) -> 14 mins | S15: =VLOOKUP(A15,'Travel Times'!$A$1:$E$1000,5,0) -> 6 mins | T15: Lunch: Chelsea said looks good for pizza, as ChaptGPT recommended | V15: Anacapri | W15: Capri
A16: Ristorante Pulalli | B16: Capri | C16: Restaurant (Dinner) | D16: 🍽️ | E16: Traditional Capri cuisine with well-executed classics. Established restaurant with reliable quality | F16: Solid reputation among travel guides, traditional Capri dining, reliable choice | G16: 7:00 PM - 11:00 PM | H16: $70-100 USD for 2 | I16: Piazza Umberto I, 4, 80073 Capri NA, Italy | J16: 40.5508286, 14.2427963 | K16: 40.550829 | L16: 14.242796 | M16: https://www.google.com/maps/search/Ristorante%20Pulalli%2C%20Capri%2C%20Italy | N16: Manus | O16: Manus Capri Restaurants | P16: =VLOOKUP(B16,$V$3:$W$100,2,0) -> Capri | Q16: =VLOOKUP(P16,$X$3:$Y$6,2,0)&", "&P16&", Italy" -> La Residenza, Capri, Italy | R16: =VLOOKUP(A16,'Travel Times'!$A$1:$E$1000,4,0) -> 4 mins | S16: =VLOOKUP(A16,'Travel Times'!$A$1:$E$1000,5,0) -> 1 min | T16: Dinner: Reserved | V16: Amalfi | W16: Positano
A17: Gennaro Amitrano | B17: Capri | C17: Restaurant (Dinner) | D17: 🍽️ | E17: Family-run establishment with authentic Italian family hospitality. Home-style cooking with traditional recipes | F17: Personal service, family atmosphere, authentic family dining experience | G17: 7:00 PM - 10:30 PM | H17: $60-90 USD for 2 | I17: Via Marina Piccola, 120, 80073 Capri NA, Italy | J17: 40.545691, 14.2355518 | K17: 40.545691 | L17: 14.235552 | M17: https://www.google.com/maps/search/Gennaro%20Amitrano%2C%20Capri%2C%20Italy | N17: Manus | O17: Manus Capri Restaurants | P17: =VLOOKUP(B17,$V$3:$W$100,2,0) -> Capri | Q17: =VLOOKUP(P17,$X$3:$Y$6,2,0)&", "&P17&", Italy" -> La Residenza, Capri, Italy | R17: =VLOOKUP(A17,'Travel Times'!$A$1:$E$1000,4,0) -> 22 mins | S17: =VLOOKUP(A17,'Travel Times'!$A$1:$E$1000,5,0) -> 8 mins | V17: Amalfi Coast | W17: Positano
A18: Ziqù Restaurant | B18: Capri | C18: Restaurant (Dinner) | D18: 🍽️ | E18: Highest rated restaurant with 4.9/5 from 269 reviews. Italian and seafood cuisine, exceptional quality | F18: Limited reviews suggest exclusivity, highest rating on TripAdvisor, exceptional quality | G18: 7:00 PM - 11:00 PM | H18: $150-200+ USD for 2 | I18: Via Marina Grande, 191, 80073 Capri NA, Italy | J18: 40.55633, 14.2361122 | K18: 40.55633 | L18: 14.236112 | M18: https://www.google.com/maps/search/Ziq%C3%B9%20Restaurant%2C%20Capri%2C%20Italy | N18: Manus | O18: Manus Capri Restaurants | P18: =VLOOKUP(B18,$V$3:$W$100,2,0) -> Capri | Q18: =VLOOKUP(P18,$X$3:$Y$6,2,0)&", "&P18&", Italy" -> La Residenza, Capri, Italy | R18: =VLOOKUP(A18,'Travel Times'!$A$1:$E$1000,4,0) -> 19 mins | S18: =VLOOKUP(A18,'Travel Times'!$A$1:$E$1000,5,0) -> 7 mins | V18: Furore | W18: Positano
A19: Da Tonino | B19: Capri | C19: Restaurant (Lunch/Dinner) | D19: 🍽️ | E19: Established local favorite with 1,304 reviews. Consistently good quality, dependable dining option | F19: Reliable choice, established reputation, consistent quality | G19: 12:00 PM - 3:00 PM & 7:00 PM - 10:30 PM | H19: $70-100 USD for 2 | I19: Via Dentecale, 14, 80073 Capri NA, Italy | J19: 40.5497881, 14.2450745 | K19: 40.549788 | L19: 14.245074 | M19: https://www.google.com/maps/search/Da%20Tonino%2C%20Capri%2C%20Italy | N19: Manus | O19: Manus Capri Restaurants | P19: =VLOOKUP(B19,$V$3:$W$100,2,0) -> Capri | Q19: =VLOOKUP(P19,$X$3:$Y$6,2,0)&", "&P19&", Italy" -> La Residenza, Capri, Italy | R19: =VLOOKUP(A19,'Travel Times'!$A$1:$E$1000,4,0) -> 18 mins | S19: =VLOOKUP(A19,'Travel Times'!$A$1:$E$1000,5,0) -> 6 mins | V19: Bomerano (start) to Nocelle (end) | W19: Positano
A20: Artemisia Domus (Naples) | B20: =substitute(RIGHT(A20,len(A20)-FIND("(",A20)),")","") -> Naples | C20: Hotel | D20: 🏨 | E20: Boutique hotel in central Naples with elegant design and great breakfast. | F20: Boutique B&B with stylish rooms; complimentary breakfast and pre-arrival concierge. | G20: 24/7 (hotel) | H20: $900 for two | I20: Via dei Carrozzieri a Monteoliveto 13, 80134 Napoli, Italy | J20: 40.845634, 14.2517054 | K20: =IFERROR(__xludf.DUMMYFUNCTION("SPLIT(J20,"", "")"),40.845634) -> 40.845634 | L20: =IFERROR(__xludf.DUMMYFUNCTION("""COMPUTED_VALUE"""),14.2517054) -> 14.251705 | M20: =HYPERLINK("https://www.google.com/maps/search/"&ENCODEURL(A20&", "&21&", Italy")) -> https://www.google.com/maps/search/Artemisia%20Domus%20%28Naples%29%2C%2021%2C%20Italy | N20: ChatGPT - https://chatgpt.com/c/6846f0da-7884-8009-ad13-dba01dfa021d | O20: ChatGPT Itinerary 1 | P20: =VLOOKUP(B20,$V$3:$W$100,2,0) -> Naples | Q20: =VLOOKUP(P20,$X$3:$Y$6,2,0)&", "&P20&", Italy" -> Relais sul Mare Boutique Hotel, Naples, Italy | R20: =VLOOKUP(A20,'Travel Times'!$A$1:$E$1000,4,0) -> 29 mins | S20: =VLOOKUP(A20,'Travel Times'!$A$1:$E$1000,5,0) -> 9 mins | V20: Praiano-Positano | W20: Positano
A21: The Britannique by Hilton (Naples) | B21: =substitute(RIGHT(A21,len(A21)-FIND("(",A21)),")","") -> Naples | C21: Hotel | D21: 🏨 | E21: Modern hotel in Naples with panoramic rooftop bar and sea views. | F21: Modern hotel with rooftop bar & spa; reserve for sunset cocktails. | G21: 24/7 (hotel) | H21: $500 for two | I21: C.so Vittorio Emanuele, 133, 80121 Napoli NA, Italy | J21: 40.836915, 14.2296809 | K21: =IFERROR(__xludf.DUMMYFUNCTION("SPLIT(J21,"", "")"),40.836915) -> 40.836915 | L21: =IFERROR(__xludf.DUMMYFUNCTION("""COMPUTED_VALUE"""),14.2296809) -> 14.229681 | M21: =HYPERLINK("https://www.google.com/maps/search/"&ENCODEURL(A21&", "&21&", Italy")) -> https://www.google.com/maps/search/The%20Britannique%20by%20Hilton%20%28Naples%29%2C%2021%2C%20Italy | N21: ChatGPT - https://chatgpt.com/c/6846f0da-7884-8009-ad13-dba01dfa021d | O21: ChatGPT Itinerary 1 | P21: =VLOOKUP(B21,$V$3:$W$100,2,0) -> Naples | Q21: =VLOOKUP(P21,$X$3:$Y$6,2,0)&", "&P21&", Italy" -> Relais sul Mare Boutique Hotel, Naples, Italy | R21: =VLOOKUP(A21,'Travel Times'!$A$1:$E$1000,4,0) -> 39 mins | S21: =VLOOKUP(A21,'Travel Times'!$A$1:$E$1000,5,0) -> 11 mins | V21: Montepertuso (above Positano) | W21: Positano
A22: Gino Sorbillo (Naples) | B22: =substitute(RIGHT(A22,len(A22)-FIND("(",A22)),")","") -> Naples | C22: Restaurant | D22: 🍕 | E22: One of Naples’ most iconic pizzerias in the historic center. | F22: Famous Neapolitan pizza, long lines – best to arrive just before opening; try their pineapple pizza. | G22: Mon–Sat 12:00–15:30 & 19:00–23:30; Sun closed (fontelina-capri.com, happycow.net, perplexity.ai, tripadvisor.com) | H22: $70 for two | I22: Via dei Tribunali 32, 80138 Napoli, Italy | J22: 40.850421, 14.2553143 | K22: =IFERROR(__xludf.DUMMYFUNCTION("SPLIT(J22,"", "")"),40.850421) -> 40.850421 | L22: =IFERROR(__xludf.DUMMYFUNCTION("""COMPUTED_VALUE"""),14.2553143) -> 14.255314 | M22: =HYPERLINK("https://www.google.com/maps/search/"&ENCODEURL(A22&", "&21&", Italy")) -> https://www.google.com/maps/search/Gino%20Sorbillo%20%28Naples%29%2C%2021%2C%20Italy | N22: ChatGPT - https://chatgpt.com/c/6846f0da-7884-8009-ad13-dba01dfa021d | O22: ChatGPT Itinerary 1 | P22: =VLOOKUP(B22,$V$3:$W$100,2,0) -> Naples | Q22: =VLOOKUP(P22,$X$3:$Y$6,2,0)&", "&P22&", Italy" -> Relais sul Mare Boutique Hotel, Naples, Italy | R22: =VLOOKUP(A22,'Travel Times'!$A$1:$E$1000,4,0) -> 39 mins | S22: =VLOOKUP(A22,'Travel Times'!$A$1:$E$1000,5,0) -> 23 mins
A23: L’Antica Pizzeria da Michele (Naples) | B23: =substitute(RIGHT(A23,len(A23)-FIND("(",A23)),")","") -> Naples | C23: Restaurant | D23: 🍕 | E23: Historic, no-frills spot for some of Naples’ best traditional pizza. | F23: Historic classic; very simple menu (Margherita/Marinara only). | G23: Typically 11:00–23:00, often closes Mon (confirm) | H23: $70 for two | I23: Via Cesare Sersale 1, 80139 Napoli | J23: 40.8497752, 14.2632371 | K23: =IFERROR(__xludf.DUMMYFUNCTION("SPLIT(J23,"", "")"),40.8497752) -> 40.849775 | L23: =IFERROR(__xludf.DUMMYFUNCTION("""COMPUTED_VALUE"""),14.2632371) -> 14.263237 | M23: =HYPERLINK("https://www.google.com/maps/search/"&ENCODEURL(A23&", "&21&", Italy")) -> https://www.google.com/maps/search/L%E2%80%99Antica%20Pizzeria%20da%20Michele%20%28Naples%29%2C%2021%2C%20Italy | N23: ChatGPT - https://chatgpt.com/c/6846f0da-7884-8009-ad13-dba01dfa021d | O23: ChatGPT Itinerary 1 | P23: =VLOOKUP(B23,$V$3:$W$100,2,0) -> Naples | Q23: =VLOOKUP(P23,$X$3:$Y$6,2,0)&", "&P23&", Italy" -> Relais sul Mare Boutique Hotel, Naples, Italy | R23: =VLOOKUP(A23,'Travel Times'!$A$1:$E$1000,4,0) -> 39 mins | S23: =VLOOKUP(A23,'Travel Times'!$A$1:$E$1000,5,0) -> 13 mins
A24: Gay‑Odin (Naples) | B24: =substitute(RIGHT(A24,len(A24)-FIND("(",A24)),")","") -> Naples | C24: Shop | D24: 🍦 | E24: Artisanal chocolate shop famous for its gelato and heritage sweets. | F24: Artisanal chocolates & gelato; great for gifting or a quick treat. | G24: 10:00–20:00 daily | H24: $60 for two | I24: Via San Biagio dei Librai 44, 80138 Napoli | J24: 40.84968560000001, 14.2589603 | K24: =IFERROR(__xludf.DUMMYFUNCTION("SPLIT(J24,"", "")"),40.8496856) -> 40.849686 | L24: =IFERROR(__xludf.DUMMYFUNCTION("""COMPUTED_VALUE"""),14.2589603) -> 14.25896 | M24: =HYPERLINK("https://www.google.com/maps/search/"&ENCODEURL(A24&", "&21&", Italy")) -> https://www.google.com/maps/search/Gay%E2%80%91Odin%20%28Naples%29%2C%2021%2C%20Italy | N24: ChatGPT - https://chatgpt.com/c/6846f0da-7884-8009-ad13-dba01dfa021d | O24: ChatGPT Itinerary 1 | P24: =VLOOKUP(B24,$V$3:$W$100,2,0) -> Naples | Q24: =VLOOKUP(P24,$X$3:$Y$6,2,0)&", "&P24&", Italy" -> Relais sul Mare Boutique Hotel, Naples, Italy | R24: =VLOOKUP(A24,'Travel Times'!$A$1:$E$1000,4,0) -> 44 mins | S24: =VLOOKUP(A24,'Travel Times'!$A$1:$E$1000,5,0) -> 11 mins
A25: Hotel Villa Brunella (Capri) | B25: =substitute(RIGHT(A25,len(A25)-FIND("(",A25)),")","") -> Capri | C25: Hotel | D25: 🏨 | E25: Romantic and quiet boutique hotel with stunning terrace views. | F25: Terrace views over Marina Piccola; request sea-view rooms and private shuttle to Capri town. | G25: 24/7 (hotel) | H25: 3000 | I25: 80073, Via Tragara, 24a, 80073 Capri NA, Italy | J25: 40.5461439, 14.2495769 | K25: =IFERROR(__xludf.DUMMYFUNCTION("SPLIT(J25,"", "")"),40.5461439) -> 40.546144 | L25: =IFERROR(__xludf.DUMMYFUNCTION("""COMPUTED_VALUE"""),14.2495769) -> 14.249577 | M25: =HYPERLINK("https://www.google.com/maps/search/"&ENCODEURL(A25&", "&21&", Italy")) -> https://www.google.com/maps/search/Hotel%20Villa%20Brunella%20%28Capri%29%2C%2021%2C%20Italy | N25: ChatGPT - https://chatgpt.com/c/6846f0da-7884-8009-ad13-dba01dfa021d | O25: ChatGPT Itinerary 1 | P25: =VLOOKUP(B25,$V$3:$W$100,2,0) -> Capri | Q25: =VLOOKUP(P25,$X$3:$Y$6,2,0)&", "&P25&", Italy" -> La Residenza, Capri, Italy | R25: =VLOOKUP(A25,'Travel Times'!$A$1:$E$1000,4,0) -> 12 mins | S25: =VLOOKUP(A25,'Travel Times'!$A$1:$E$1000,5,0) -> 1 min
A26: JK Place Capri (Capri) | B26: =substitute(RIGHT(A26,len(A26)-FIND("(",A26)),")","") -> Capri | C26: Hotel | D26: 🏨 | E26: Luxury waterfront hotel near Marina Grande with impeccable service. | F26: Luxury beachfront hotel; ideal for romantic dinners by the sea. | G26: 24/7 (hotel) | H26: 3000 | I26: Via Roma 71, 80073 Capri NA, Italy | J26: 40.54987939999999, 14.2401657 | K26: =IFERROR(__xludf.DUMMYFUNCTION("SPLIT(J26,"", "")"),40.5498793999999) -> 40.549879 | L26: =IFERROR(__xludf.DUMMYFUNCTION("""COMPUTED_VALUE"""),14.2401657) -> 14.240166 | M26: =HYPERLINK("https://www.google.com/maps/search/"&ENCODEURL(A26&", "&21&", Italy")) -> https://www.google.com/maps/search/JK%20Place%20Capri%20%28Capri%29%2C%2021%2C%20Italy | N26: ChatGPT - https://chatgpt.com/c/6846f0da-7884-8009-ad13-dba01dfa021d | O26: ChatGPT Itinerary 1 | P26: =VLOOKUP(B26,$V$3:$W$100,2,0) -> Capri | Q26: =VLOOKUP(P26,$X$3:$Y$6,2,0)&", "&P26&", Italy" -> La Residenza, Capri, Italy | R26: =VLOOKUP(A26,'Travel Times'!$A$1:$E$1000,4,0) -> 23 mins | S26: =VLOOKUP(A26,'Travel Times'!$A$1:$E$1000,5,0) -> 8 mins
A27: La Fontelina (Capri) | B27: =substitute(RIGHT(A27,len(A27)-FIND("(",A27)),")","") -> Capri | C27: Beach Club | D27: ⛱️ | E27: Iconic beach club near Faraglioni rocks with chic loungers and fresh seafood. | F27: Lunch-only in summer; €190 p.p. min. spend in high season; shuttle boat returns 15:00–18:30. | G27: Beach: 9:00–19:00; Restaurant: 12:30–16:00 daily | H27: $200 for two | I27: Località Faraglioni, 80073 Capri NA, Italy | J27: 40.5434303, 14.2523999 | K27: =IFERROR(__xludf.DUMMYFUNCTION("SPLIT(J27,"", "")"),40.5434303) -> 40.54343 | L27: =IFERROR(__xludf.DUMMYFUNCTION("""COMPUTED_VALUE"""),14.2523999) -> 14.2524 | M27: =HYPERLINK("https://www.google.com/maps/search/"&ENCODEURL(A27&", "&21&", Italy")) -> https://www.google.com/maps/search/La%20Fontelina%20%28Capri%29%2C%2021%2C%20Italy | N27: ChatGPT - https://chatgpt.com/c/6846f0da-7884-8009-ad13-dba01dfa021d | O27: ChatGPT Itinerary 1 | P27: =VLOOKUP(B27,$V$3:$W$100,2,0) -> Capri | Q27: =VLOOKUP(P27,$X$3:$Y$6,2,0)&", "&P27&", Italy" -> La Residenza, Capri, Italy | R27: =VLOOKUP(A27,'Travel Times'!$A$1:$E$1000,4,0) -> 23 mins | S27: =VLOOKUP(A27,'Travel Times'!$A$1:$E$1000,5,0) -> 1 min
A28: Da Gelsomina (Capri) | B28: =substitute(RIGHT(A28,len(A28)-FIND("(",A28)),")","") -> Capri | C28: Restaurant | D28: 🍷 | E28: Charming vineyard-side restaurant in Anacapri with local dishes and wine. | F28: Hilltop Anacapri vineyard spot; dress smart-casual. | G28: ~12:00–15:00 & 19:00–22:00 | H28: $100 for two | I28: Via Migliara, 72, 80071 Anacapri NA, Italy | J28: 40.5409493, 14.2102105 | K28: =IFERROR(__xludf.DUMMYFUNCTION("SPLIT(J28,"", "")"),40.5409493) -> 40.540949 | L28: =IFERROR(__xludf.DUMMYFUNCTION("""COMPUTED_VALUE"""),14.2102105) -> 14.210211 | M28: =HYPERLINK("https://www.google.com/maps/search/"&ENCODEURL(A28&", "&21&", Italy")) -> https://www.google.com/maps/search/Da%20Gelsomina%20%28Capri%29%2C%2021%2C%20Italy | N28: ChatGPT - https://chatgpt.com/c/6846f0da-7884-8009-ad13-dba01dfa021d | O28: ChatGPT Itinerary 1 | P28: =VLOOKUP(B28,$V$3:$W$100,2,0) -> Capri | Q28: =VLOOKUP(P28,$X$3:$Y$6,2,0)&", "&P28&", Italy" -> La Residenza, Capri, Italy | R28: =VLOOKUP(A28,'Travel Times'!$A$1:$E$1000,4,0) -> 1 hour 14 mins | S28: =VLOOKUP(A28,'Travel Times'!$A$1:$E$1000,5,0) -> 19 mins
A29: Belmond Hotel Caruso (Ravello) | B29: =substitute(RIGHT(A29,len(A29)-FIND("(",A29)),")","") -> Ravello | C29: Hotel | D29: 🏨 | E29: Historic palace hotel with an infinity pool overlooking the Amalfi Coast. | F29: Iconic infinity pool; spa and morning yoga available. | G29: Hotel: 24/7; Pool: 08:00–19:00 | H29: 5000 | I29: Piazza San Giovanni del Toro 2, 84010 Ravello (SA), Italy | J29: 40.6514101, 14.6129723 | K29: =IFERROR(__xludf.DUMMYFUNCTION("SPLIT(J29,"", "")"),40.6514101) -> 40.65141 | L29: =IFERROR(__xludf.DUMMYFUNCTION("""COMPUTED_VALUE"""),14.6129723) -> 14.612972 | M29: =HYPERLINK("https://www.google.com/maps/search/"&ENCODEURL(A29&", "&21&", Italy")) -> https://www.google.com/maps/search/Belmond%20Hotel%20Caruso%20%28Ravello%29%2C%2021%2C%20Italy | N29: ChatGPT - https://chatgpt.com/c/6846f0da-7884-8009-ad13-dba01dfa021d | O29: ChatGPT Itinerary 1 | P29: =VLOOKUP(B29,$V$3:$W$100,2,0) -> Ravello | Q29: =VLOOKUP(P29,$X$3:$Y$6,2,0)&", "&P29&", Italy" -> Hotel Rufolo, Ravello, Italy | R29: =VLOOKUP(A29,'Travel Times'!$A$1:$E$1000,4,0) -> 8 mins | S29: =VLOOKUP(A29,'Travel Times'!$A$1:$E$1000,5,0) -> 3 mins
A30: Villa Maria Ravello | B30: Ravello | C30: Hotel | D30: 🏨 | E30: Peaceful hotel with garden terraces and a focus on local cuisine. | F30: Quiet boutique hotel; known for homegrown lemon-themed dishes. | G30: 24/7 (hotel); breakfast until ~10:30 | H30: $3000 for two | I30: Via Santa Chiara, 2, 84010 Ravello SA, Italy | J30: 40.6468104, 14.6103006 | K30: =IFERROR(__xludf.DUMMYFUNCTION("SPLIT(J30,"", "")"),40.6468104) -> 40.64681 | L30: =IFERROR(__xludf.DUMMYFUNCTION("""COMPUTED_VALUE"""),14.6103006) -> 14.610301 | M30: =HYPERLINK("https://www.google.com/maps/search/"&ENCODEURL(A30&", "&21&", Italy")) -> https://www.google.com/maps/search/Villa%20Maria%20Ravello%2C%2021%2C%20Italy | N30: ChatGPT - https://chatgpt.com/c/6846f0da-7884-8009-ad13-dba01dfa021d | O30: ChatGPT Itinerary 1 | P30: =VLOOKUP(B30,$V$3:$W$100,2,0) -> Ravello | Q30: =VLOOKUP(P30,$X$3:$Y$6,2,0)&", "&P30&", Italy" -> Hotel Rufolo, Ravello, Italy | R30: =VLOOKUP(A30,'Travel Times'!$A$1:$E$1000,4,0) -> 4 mins | S30: =VLOOKUP(A30,'Travel Times'!$A$1:$E$1000,5,0) -> 1 min
A31: Villa Rufolo (Ravello) | B31: =substitute(RIGHT(A31,len(A31)-FIND("(",A31)),")","") -> Ravello | C31: Attraction | D31: 🏛️ | E31: Historic villa and gardens with panoramic views and concerts. | F31: Historic gardens with panoramic terrace; host of summer music festivals. | G31: Gardens: ~09:00–19:00 | H31: $120 for two | I31: Piazza Duomo, 84010 Ravello (SA), Italy | J31: 40.6491825, 14.6116481 | K31: =IFERROR(__xludf.DUMMYFUNCTION("SPLIT(J31,"", "")"),40.6491825) -> 40.649183 | L31: =IFERROR(__xludf.DUMMYFUNCTION("""COMPUTED_VALUE"""),14.6116481) -> 14.611648 | M31: =HYPERLINK("https://www.google.com/maps/search/"&ENCODEURL(A31&", "&21&", Italy")) -> https://www.google.com/maps/search/Villa%20Rufolo%20%28Ravello%29%2C%2021%2C%20Italy | N31: ChatGPT - https://chatgpt.com/c/6846f0da-7884-8009-ad13-dba01dfa021d | O31: ChatGPT Itinerary 1 | P31: =VLOOKUP(B31,$V$3:$W$100,2,0) -> Ravello | Q31: =VLOOKUP(P31,$X$3:$Y$6,2,0)&", "&P31&", Italy" -> Hotel Rufolo, Ravello, Italy | R31: =VLOOKUP(A31,'Travel Times'!$A$1:$E$1000,4,0) -> 2 mins | S31: =VLOOKUP(A31,'Travel Times'!$A$1:$E$1000,5,0) -> 1 min
A32: Wagner Tours (Wine Experience, Ravello) | B32: =substitute(RIGHT(A32,len(A32)-FIND("(",A32)),")","") -> Wine Experience, Ravello | C32: Wine Tour | D32: 🍇 | E32: Guided wine experiences and tastings in Ravello. | F32: Boutique, garden-based tastings; reserve in advance. | G32: Wine tastings by appointment (~11:00–17:00) | H32: $200 for two | I32: Via del Santuario, 84010 Ravello SA, Italy | J32: 40.6515802, 14.6140606 | K32: =IFERROR(__xludf.DUMMYFUNCTION("SPLIT(J32,"", "")"),40.6515802) -> 40.65158 | L32: =IFERROR(__xludf.DUMMYFUNCTION("""COMPUTED_VALUE"""),14.6140606) -> 14.614061 | M32: =HYPERLINK("https://www.google.com/maps/search/"&ENCODEURL(A32&", "&21&", Italy")) -> https://www.google.com/maps/search/Wagner%20Tours%20%28Wine%20Experience%2C%20Ravello%29%2C%2021%2C%20Italy | N32: ChatGPT - https://chatgpt.com/c/6846f0da-7884-8009-ad13-dba01dfa021d | O32: ChatGPT Itinerary 1 | P32: =VLOOKUP(B32,$V$3:$W$100,2,0) -> Ravello | Q32: =VLOOKUP(P32,$X$3:$Y$6,2,0)&", "&P32&", Italy" -> Hotel Rufolo, Ravello, Italy | R32: =VLOOKUP(A32,'Travel Times'!$A$1:$E$1000,4,0) -> 1 min | S32: =VLOOKUP(A32,'Travel Times'!$A$1:$E$1000,5,0) -> 1 min
A33: Rossellinis at Palazzo Avino (Ravello) | B33: =substitute(RIGHT(A33,len(A33)-FIND("(",A33)),")","") -> Ravello | C33: Restaurant | D33: 🍽️ | E33: Michelin-starred restaurant with romantic cliffside dining. | F33: 1-Michelin star; dress upscale; Chef’s & Sommelier’s Tables available. | G33: Lunch: 12:30–17:00; Dinner: 18:30–22:30; closed Nov–Mar | H33: $400 for two | I33: Via San Giovanni del Toro, 84010 Ravello SA, Italy | J33: 40.6504913, 14.6129035 | K33: =IFERROR(__xludf.DUMMYFUNCTION("SPLIT(J33,"", "")"),40.6504913) -> 40.650491 | L33: =IFERROR(__xludf.DUMMYFUNCTION("""COMPUTED_VALUE"""),14.6129035) -> 14.612903 | M33: =HYPERLINK("https://www.google.com/maps/search/"&ENCODEURL(A33&", "&21&", Italy")) -> https://www.google.com/maps/search/Rossellinis%20at%20Palazzo%20Avino%20%28Ravello%29%2C%2021%2C%20Italy | N33: ChatGPT - https://chatgpt.com/c/6846f0da-7884-8009-ad13-dba01dfa021d | O33: ChatGPT Itinerary 1 | P33: =VLOOKUP(B33,$V$3:$W$100,2,0) -> Ravello | Q33: =VLOOKUP(P33,$X$3:$Y$6,2,0)&", "&P33&", Italy" -> Hotel Rufolo, Ravello, Italy | R33: =VLOOKUP(A33,'Travel Times'!$A$1:$E$1000,4,0) -> 8 mins | S33: =VLOOKUP(A33,'Travel Times'!$A$1:$E$1000,5,0) -> 2 mins
A34: Casa Angelina (Praiano) | B34: =substitute(RIGHT(A34,len(A34)-FIND("(",A34)),")","") -> Praiano | C34: Hotel | D34: 🏨 | E34: Minimalist, adults-only luxury hotel with modern art and sea views. | F34: Adults-only, minimalist luxury; great for spa days and rooftop cocktails. | G34: Hotel: 24/7; Pool: ~08:00–19:00 | H34: $5000 for two | I34: Piazza Antiche Mura, 22, 84010 Praiano SA, Italy | J34: 40.6117319, 14.5335099 | K34: =IFERROR(__xludf.DUMMYFUNCTION("SPLIT(J34,"", "")"),40.6117319) -> 40.611732 | L34: =IFERROR(__xludf.DUMMYFUNCTION("""COMPUTED_VALUE"""),14.5335099) -> 14.53351 | M34: =HYPERLINK("https://www.google.com/maps/search/"&ENCODEURL(A34&", "&21&", Italy")) -> https://www.google.com/maps/search/Casa%20Angelina%20%28Praiano%29%2C%2021%2C%20Italy | N34: ChatGPT - https://chatgpt.com/c/6846f0da-7884-8009-ad13-dba01dfa021d | O34: ChatGPT Itinerary 1 | P34: =VLOOKUP(B34,$V$3:$W$100,2,0) -> Positano | Q34: =VLOOKUP(P34,$X$3:$Y$6,2,0)&", "&P34&", Italy" -> Hotel Savoia, Positano, Italy | R34: =VLOOKUP(A34,'Travel Times'!$A$1:$E$1000,4,0) -> 1 hour 21 mins | S34: =VLOOKUP(A34,'Travel Times'!$A$1:$E$1000,5,0) -> 13 mins
A35: Monastero Santa Rosa Hotel (Conca dei Marini) | B35: =substitute(RIGHT(A35,len(A35)-FIND("(",A35)),")","") -> Conca dei Marini | C35: Hotel | D35: 🏨 | E35: 5-star cliffside monastery-turned-hotel with a world-class spa. | F35: Ex-monastery with cliffside spa; Il Refettorio located onsite. | G35: Hotel: 24/7; Spa & pool open ~09:00–19:00 | H35: 3000 | I35: Via Krupp, 11, 84010 Conca dei Marini SA, Italy | J35: 40.6163236, 14.5753912 | K35: =IFERROR(__xludf.DUMMYFUNCTION("SPLIT(J35,"", "")"),40.6163236) -> 40.616324 | L35: =IFERROR(__xludf.DUMMYFUNCTION("""COMPUTED_VALUE"""),14.5753912) -> 14.575391 | M35: =HYPERLINK("https://www.google.com/maps/search/"&ENCODEURL(A35&", "&21&", Italy")) -> https://www.google.com/maps/search/Monastero%20Santa%20Rosa%20Hotel%20%28Conca%20dei%20Marini%29%2C%2021%2C%20Italy | N35: ChatGPT - https://chatgpt.com/c/6846f0da-7884-8009-ad13-dba01dfa021d | O35: ChatGPT Itinerary 1 | P35: =VLOOKUP(B35,$V$3:$W$100,2,0) -> Positano | Q35: =VLOOKUP(P35,$X$3:$Y$6,2,0)&", "&P35&", Italy" -> Hotel Savoia, Positano, Italy | R35: =VLOOKUP(A35,'Travel Times'!$A$1:$E$1000,4,0) -> 4 hours 42 mins | S35: =VLOOKUP(A35,'Travel Times'!$A$1:$E$1000,5,0) -> 39 mins
A36: One Fire Beach Club (Praiano) | B36: =substitute(RIGHT(A36,len(A36)-FIND("(",A36)),")","") -> Praiano | C36: Beach Club | D36: ⛱️ | E36: Laid-back beach club known for music, fire shows, and chill vibes. | F36: Casual beach club with fire shows & DJ sets; bring cash. | G36: ~09:00–18:00 | H36: $200 for two | I36: Marina di Praia, 84017 Praiano SA, Italy | J36: 40.6134729, 14.5394424 | K36: =IFERROR(__xludf.DUMMYFUNCTION("SPLIT(J36,"", "")"),40.6134729) -> 40.613473 | L36: =IFERROR(__xludf.DUMMYFUNCTION("""COMPUTED_VALUE"""),14.5394424) -> 14.539442 | M36: =HYPERLINK("https://www.google.com/maps/search/"&ENCODEURL(A36&", "&21&", Italy")) -> https://www.google.com/maps/search/One%20Fire%20Beach%20Club%20%28Praiano%29%2C%2021%2C%20Italy | N36: ChatGPT - https://chatgpt.com/c/6846f0da-7884-8009-ad13-dba01dfa021d | O36: ChatGPT Itinerary 1 | P36: =VLOOKUP(B36,$V$3:$W$100,2,0) -> Positano | Q36: =VLOOKUP(P36,$X$3:$Y$6,2,0)&", "&P36&", Italy" -> Hotel Savoia, Positano, Italy | R36: =VLOOKUP(A36,'Travel Times'!$A$1:$E$1000,4,0) -> 1 hour 27 mins | S36: =VLOOKUP(A36,'Travel Times'!$A$1:$E$1000,5,0) -> 13 mins
A37: Lido degli Artisti (Praiano) | B37: =substitute(RIGHT(A37,len(A37)-FIND("(",A37)),")","") -> Praiano | C37: Beach Club | D37: ⛱️ | E37: Cozy beach with sunbeds and a dramatic cliff backdrop. | F37: Cliffside sunbeds for rent; small snack kiosk; relaxed vibe. | G37: ~09:00–18:00 | H37: $500 for two | I37: Località La Gavitella, 84017 Praiano SA, Italy | J37: 40.6138362, 14.5204525 | K37: =IFERROR(__xludf.DUMMYFUNCTION("SPLIT(J37,"", "")"),40.6138362) -> 40.613836 | L37: =IFERROR(__xludf.DUMMYFUNCTION("""COMPUTED_VALUE"""),14.5204525) -> 14.520452 | M37: =HYPERLINK("https://www.google.com/maps/search/"&ENCODEURL(A37&", "&21&", Italy")) -> https://www.google.com/maps/search/Lido%20degli%20Artisti%20%28Praiano%29%2C%2021%2C%20Italy | N37: ChatGPT - https://chatgpt.com/c/6846f0da-7884-8009-ad13-dba01dfa021d | O37: ChatGPT Itinerary 1 | P37: =VLOOKUP(B37,$V$3:$W$100,2,0) -> Positano | Q37: =VLOOKUP(P37,$X$3:$Y$6,2,0)&", "&P37&", Italy" -> Hotel Savoia, Positano, Italy | R37: =VLOOKUP(A37,'Travel Times'!$A$1:$E$1000,4,0) -> 4 hours 40 mins | S37: =VLOOKUP(A37,'Travel Times'!$A$1:$E$1000,5,0) -> 38 mins
A38: Il Refettorio (Monastero Santa Rosa) | B38: =substitute(RIGHT(A38,len(A38)-FIND("(",A38)),")","") -> Monastero Santa Rosa | C38: Restaurant | D38: 🍽️ | E38: Michelin-starred dining within the Monastero Santa Rosa Hotel. | F38: Michelin-starred in monastery; dress smart-casual, reservations required. | G38: Dinner only, ~19:00–22:00 | H38: $200 for two | I38: Via Krupp, 11, 84010 Conca dei Marini SA, Italy | J38: 40.6163236, 14.5753912 | K38: =IFERROR(__xludf.DUMMYFUNCTION("SPLIT(J38,"", "")"),40.6163236) -> 40.616324 | L38: =IFERROR(__xludf.DUMMYFUNCTION("""COMPUTED_VALUE"""),14.5753912) -> 14.575391 | M38: =HYPERLINK("https://www.google.com/maps/search/"&ENCODEURL(A38&", "&21&", Italy")) -> https://www.google.com/maps/search/Il%20Refettorio%20%28Monastero%20Santa%20Rosa%29%2C%2021%2C%20Italy | N38: ChatGPT - https://chatgpt.com/c/6846f0da-7884-8009-ad13-dba01dfa021d | O38: ChatGPT Itinerary 1 | P38: =VLOOKUP(B38,$V$3:$W$100,2,0) -> Positano | Q38: =VLOOKUP(P38,$X$3:$Y$6,2,0)&", "&P38&", Italy" -> Hotel Savoia, Positano, Italy | R38: =VLOOKUP(A38,'Travel Times'!$A$1:$E$1000,4,0) -> 4 hours 42 mins | S38: =VLOOKUP(A38,'Travel Times'!$A$1:$E$1000,5,0) -> 39 mins
A39: Kasai (Praiano) | B39: =substitute(RIGHT(A39,len(A39)-FIND("(",A39)),")","") -> Praiano | C39: Restaurant | D39: 🍝 | E39: Locally loved spot with fresh seafood and sunset views. | F39: Fresh seafood & sushi fusion; sunset tables book fast. | G39: ~12:00–15:00 & 19:00–22:00 | H39: $2000 for two | I39: Via G. Capriglione, 2, 84017 Praiano SA, Italy | J39: 40.6087328, 14.5268626 | K39: =IFERROR(__xludf.DUMMYFUNCTION("SPLIT(J39,"", "")"),40.6087328) -> 40.608733 | L39: =IFERROR(__xludf.DUMMYFUNCTION("""COMPUTED_VALUE"""),14.5268626) -> 14.526863 | M39: =HYPERLINK("https://www.google.com/maps/search/"&ENCODEURL(A39&", "&21&", Italy")) -> https://www.google.com/maps/search/Kasai%20%28Praiano%29%2C%2021%2C%20Italy | N39: ChatGPT - https://chatgpt.com/c/6846f0da-7884-8009-ad13-dba01dfa021d | O39: ChatGPT Itinerary 1 | P39: =VLOOKUP(B39,$V$3:$W$100,2,0) -> Positano | Q39: =VLOOKUP(P39,$X$3:$Y$6,2,0)&", "&P39&", Italy" -> Hotel Savoia, Positano, Italy | R39: =VLOOKUP(A39,'Travel Times'!$A$1:$E$1000,4,0) -> 1 hour 42 mins | S39: =VLOOKUP(A39,'Travel Times'!$A$1:$E$1000,5,0) -> 15 mins
A40: La Tagliata (Positano) | B40: =substitute(RIGHT(A40,len(A40)-FIND("(",A40)),")","") -> Positano | C40: Cooking Class | D40: 👩‍🍳 | E40: Rustic, family-run restaurant offering fun and hearty cooking classes. | F40: Rustic family meal & cooking class; farm-fresh ingredients; open-air terrace. | G40: Lunch & Dinner (check seasonally) | H40: $150 for two | I40: Via Tagliata, 1, 84017 Positano SA, Italy | J40: 40.6332256, 14.4930882 | K40: =IFERROR(__xludf.DUMMYFUNCTION("SPLIT(J40,"", "")"),40.6332256) -> 40.633226 | L40: =IFERROR(__xludf.DUMMYFUNCTION("""COMPUTED_VALUE"""),14.4930882) -> 14.493088 | M40: =HYPERLINK("https://www.google.com/maps/search/"&ENCODEURL(A40&", "&21&", Italy")) -> https://www.google.com/maps/search/La%20Tagliata%20%28Positano%29%2C%2021%2C%20Italy | N40: ChatGPT - https://chatgpt.com/c/6846f0da-7884-8009-ad13-dba01dfa021d | O40: ChatGPT Itinerary 1 | P40: =VLOOKUP(B40,$V$3:$W$100,2,0) -> Positano | Q40: =VLOOKUP(P40,$X$3:$Y$6,2,0)&", "&P40&", Italy" -> Hotel Savoia, Positano, Italy | R40: =VLOOKUP(A40,'Travel Times'!$A$1:$E$1000,4,0) -> 47 mins | S40: =VLOOKUP(A40,'Travel Times'!$A$1:$E$1000,5,0) -> 17 mins
...

Sheet Accomodations
A1: Hotel | B1: Price per Night (Aug/Sep) | C1: Beach Club | D1: Ferry Access (1-10) | E1: da Paolino (1-10) | F1: Il Riccio (1-10) | G1: La Fontelina (1-10) | H1: Boat Day (1-10) | I1: Da Gioia (1-10) | J1: L'Olivo & Monte Solaro (1-10)
A2: Hotel La Palma | B2: €800-1200 | C2: Yes (Da Gioia) | D2: 8 | E2: 6 | F2: 3 | G2: 9 | H2: 9 | I2: 10 | J2: 3 | K2: =AVERAGE(D2:J2) -> 6.8571429
A3: J.K. Place Capri | B3: €400-600 | C3: No | D3: 10 | E3: 9 | F3: 3 | G3: 7 | H3: 10 | I3: 7 | J3: 3 | K3: =AVERAGE(D3:J3) -> 7
A4: La Minerva | B4: €250-400 | C4: No | D4: 7 | E4: 5 | F4: 3 | G4: 8 | H4: 8 | I4: 8 | J4: 3 | K4: =AVERAGE(D4:J4) -> 6
A5: Punta Tragara | B5: €500-1200 | C5: No | D5: 6 | E5: 4 | F5: 3 | G5: 10 | H5: 8 | I5: 7 | J5: 3 | K5: =AVERAGE(D5:J5) -> 5.8571429
A6: Grand Hotel Quisisana | B6: €800-1500 | C6: No | D6: 8 | E6: 5 | F6: 3 | G6: 8 | H6: 9 | I6: 8 | J6: 3 | K6: =AVERAGE(D6:J6) -> 6.2857143
A7: Capri Tiberio Palace | B7: €400-800 | C7: No | D7: 7 | E7: 5 | F7: 3 | G7: 8 | H7: 8 | I7: 8 | J7: 3 | K7: =AVERAGE(D7:J7) -> 6
A8: Casa Boutique by Capri 5 Senses | B8: €200-350 | C8: No | D8: 8 | E8: 5 | F8: 3 | G8: 9 | H8: 8 | I8: 8 | J8: 3 | K8: =AVERAGE(D8:J8) -> 6.2857143
A9: Capri Palace Hotel | B9: €600-1500 | C9: No | D9: 4 | E9: 3 | F9: 10 | G9: 5 | H9: 6 | I9: 5 | J9: 10 | K9: =AVERAGE(D9:J9) -> 6.1428571
A10: Airbnb in Anacapri | B10: €100-300 | C10: No | D10: 4 | E10: 3 | F10: 9 | G10: 5 | H10: 6 | I10: 5 | J10: 9 | K10: =AVERAGE(D10:J10) -> 5.8571429
C11: Rating
A12: Hotel La Palma | B12: 8363 | C12: 9.6 | F12: Villa Margherita by Belmond | G12: =11082*1.1 -> 12190.2
A13: Palazzo M | B13: =4993*1.1 -> 5492.3 | C13: 9.6 | F13: Palazzo Avino | G13: =4457*1.1 -> 4902.7
A14: J.K. Place Capri | B14: 14547 | F14: Villa Barluzzi | G14: =1244*1.1 -> 1368.4
A15: Punta Tragara | B15: 10308 | C15: 8.9 | F15: Villa Maria | G15: =894*1.1 -> 983.4
A16: La Minerva | B16: Unavailable | F16: Hotel Rufolo* | G16: 1105-1072 | H16: 4 star | I16: Sea view on Chase
A17: Capri Tiberio Palace | B17: =4779*1.1 -> 5256.9 | C17: 9.3 | F17: La Moresca | G17: 638
A18: Villa Certosa | B18: =3463*1.1 -> 3809.3 | F18: Palazzo Confalone | G18: =1111*1.1 -> 1222.1 | H18: 5 star | I18: Sea view on Chase

Sheet Unstructured Notes
A1: 45813 | B1: Gemini: Amalfi vs Puglia or both | E1: Research TODO: | F1: Amalfi Towns: Ravello, Praiano, or Conca dei Marini, Capri
A2: 45812 | B2: ChatGPT: Initial Research | E2: ✅ | F2: Research individual towns in Puglia
A3: 45813 | B3: Apple Notes: Activity Ideas | E3: ✅ | F3: Ask Manus/Gemini to compile all best restaurants, cafes, activitys, thermal pools, wineries, wine tasting classes, cooking classes, etc popular on instagram
A4: 45812 | B4: Apple Notes: Instagram Inspiration Links | E4: ✅ | F4: Notebook LM: Ask it to extract all locations from YouTube videos added
A5: 45812 | B5: Manus: Initial Research | E5: ✅ | F5: Finalize list of towns and days in each
E7: Booking TODO
E8: ✅ | F8: Flights
A9: Prompts | E9: ✅ | F9: Time Off
A10: Itinerary | B10: Hi! My girlfriend (29F) and I (33M) are planning a romantic trip to the Amalfi Coast from August 30 to September 8 (9 nights, 10 days). It’s our first time in Italy, and we’re prioritizing relaxation, scenic beauty, romance, and well-curated experiences over high-effort city touring. We’re New Yorkers, so we want to avoid anything that feels like a Times Square/cruise ship/tourist trap vibe — no cheap souvenir stands, no English-only menus, no tourist junk zones. That said, we’re totally fine with places that are popular or Instagrammable as long as they’re visually stunning, tasteful, and offer a genuine or luxurious experience (like a cliffside restaurant or a boutique hotel with views). We’d like to: Fly into Naples (arriving Aug 30), spend 1 night for the culture and pizza Ferry to Capri for 1-3 nights to explore beaches, views, and maybe a boat day. Ferry to the Amalfi Coast, staying the reset of our nights in scenic towns like Ravello, Praiano, or Conca dei Marini — open to mixing between them. Fly out of Naples on Sept 8. We’re open to renting a car if it makes things easier, but it seems ferries with a mix of private transfers and vespas might be the simplest route. We’d love help finalizing: Which towns to base ourselves in (and for how long). A day-by-day structure using “anchor activities” and optional extras. Boutique hotel or lodging suggestions in each area. Restaurant, beach club, or boat day ideas that match our taste. Best use of ferries, private drivers, or transfer timing. Here were some high-level things we were interested in generally before settling on Amalfi as our destination: - [ ] Beach day (e.g. one lined with umbrellas) - [ ] Beach club - [ ] Vespa riding - [ ] Wine tasting tour (foot, bike, or vespa, or one single location without movement if easier) - [ ] Grotta Palazzese dinner (this is in Puglia, but we'd love something with a similar memorable stunning view) - [ ] Boat day - [ ] Aperol spritz rooftop sunset - [ ] Good authentic local food - [ ] Cooking class (normal/authentic or crazy and fun like La Tagliata cooking class in Positano) - [ ] Hike (e.g. along costal cliffside or in historic towns) - [ ] If there are any notable spas, thermal pools, or ancient bath houses in the region we might be up for checking them out but that's not a priority for diverting travel When planning think: romantic, adventurous, beautiful, and upscale — but never tacky. Thanks! | E10: ✅ | F10: Book essential spots
A11: Maps | B11: Thanks, can you compile all the places you recommended into a table with the following columns: Name: The name of the location Region: The town, city, neighborhood, or region Type: The type of location (e.g. hotel, Restaurant (lunch), Restaurant (dinner) Cafe, Gelateria, Rooftop Bar, Speakeasy, etc) Emoji: A representative emoji to be used on the map as an icon. Description: A description of the spot and its general vibe Special Notes: Any special considerations (must order items, dress code, cool historical facts, etc) Hours: Hours of operation (if applicable) Cost Range: Indication of how much 2 people would be expected to spend in a visit (in USD) Address: The full address (including country) if available LatLong: The latitude and Longitude separated by a comma and space | E11: ✅ | F11: https://paolinocapri.com/en/prenota-un-tavolo/
